Workbook

Sheet Export-Zusammenfassung
B3: Dieses Dokument wurde aus Numbers exportiert und jede Tabelle in ein Excel-Arbeitsblatt umgewandelt. Alle anderen Objekte der einzelnen Numbers-Blätter wurden auf eigene Arbeitsblätter übertragen. Beachte, dass die Formelberechnungen in Excel möglicherweise anders sind.
B7: Name des Numbers-Blatts | C7: Numbers-Tabellenname | D7: Name des Excel-Arbeitsblatts
B9: Kap. 1, 2, 3
C10: Tabelle 1 | D10: Kap. 1, 2, 3
B11: Modul 1
C12: Tabelle 1 | D12: Modul 1
B13: Modul 2
C14: Tabelle 1 | D14: Modul 2
B15: Modul 3
C16: Tabelle 1 | D16: Modul 3
B17: Modul 4
C18: Tabelle 1 | D18: Modul 4
B19: Modul 5
C20: Tabelle 1 | D20: Modul 5
B21: Modul 6
C22: Tabelle 1 | D22: Modul 6
B23: Kap. 5 Pflegegrad
C24: Tabelle 1 | D24: Kap. 5 Pflegegrad
B25: Kap. 6, 7, 8, 9
C26: Tabelle 1 | D26: Kap. 6, 7, 8, 9
B27: #
C28: Tabelle 1 | D28: #

Sheet Kap. 1, 2, 3
A2: Navigation
C4: Formulargutachten zur Feststellung der Pflegebedürftigkeit (Erwachsene)
C5: Versicherter: | G5: =CONCATENATE(O24," ",E24) | Q5: Geburtsdatum: | T5: =F26
C6: Datum der Bearbeitung: | G6: =G10
C8: Allgemeines und Stammdaten
C10: Datum der Bearbeitung
C12: Erstellerin/Ersteller des Formulars
C14: Name: | M14: Vorname:
C16: Adressfeld: Auftraggeber (Pflegekasse)
C18: Straße: | M18: Haus-Nr.:
C20: PLZ: | M20: Ort:
C22: Versicherte/Versicherter
C24: Name: | M24: Vorname:
C26: Geburtsdatum:
C28: Adressfeld: Versicherte/Versicherter
C30: Straße: | M30: Haus-Nr.:
C32: PLZ: | M32: Ort:
C34: abweichende Aufenthaltsadresse
C36: Straße: | M36: Haus-Nr.:
C38: PLZ: | M38: Ort:
C40: Anlass des Antrags/Auftrags
P41: Auswahlmenü
C44: Art des Antrags/Gutachtenart
O45: Auswahlmenü
C48: Antragsdatum
C50: Eingang des Auftrags beim MDK
C52: Bisheriger Pflegegrad
C54: seit: | M54: bis:
C58: Verzögerungen im Verfahren
D60: Antragstellende Person befindet sich im Krankenhaus oder in einer Rehabilitationseinrichtung
D61: Wichtiger Behandlungstermin der antragstellenden Person
D62: Termin wurde von antragstellender Person abgesagt (sonstige Gründe)
D63: Antragstellende Person ist umgezogen
D64: Antragstellende Person wohnt im Ausland
D65: Antragstellende Person ist verstorben
D66: Antragstellende Person wurde beim angekündigten Hausbesuch nicht angetroffen
D67: Hausbesuch musste abgebrochen werden wegen Gewaltandrohung oder ähnlich schwerwiegender Gründe
D68: Hausbesuch musste abgebrochen werden wegen Verständigungsschwierigkeiten (z. B. Muttersprache)
C70: Erläuterungen:
C73: Begutachtung am: | M73: Uhrzeit:
...

Sheet Modul 1
A2: Navigation
C4: Formulargutachten zur Feststellung der Pflegebedürftigkeit (Erwachsene)
C5: Versicherter: | G5: ='Kap. 1, 2, 3'!G5 | Q5: Geburtsdatum: | T5: ='Kap. 1, 2, 3'!T5:U5
C6: Datum der Bearbeitung: | G6: ='Kap. 1, 2, 3'!G6:H6
C8: Kapitel 4 Module des Begutachtungsinstruments
C10: Modul 1 Mobilität
C12: Kriterien | L12: selbstständig | N12: überwiegend selbstständig | P12: überwiegend unselbst-ständig | R12: unselbst-ständig | T12: Punkte
A13: 1. | B13: 1 | C13: =CONCATENATE(A13,B13) -> 1.1 | D13: Positionswechsel im Bett | T13: =IF(V13<1,0,V13-1) -> 0 | V13: 0
A14: 1. | B14: 2 | C14: =CONCATENATE(A14,B14) -> 1.2 | D14: Halten einer stabilen Sitzposition | T14: =IF(V14<1,0,V14-1) -> 0 | V14: 0
A15: 1. | B15: 3 | C15: =CONCATENATE(A15,B15) -> 1.3 | D15: Umsetzen | T15: =IF(V15<1,0,V15-1) -> 0 | V15: 0
A16: 1. | B16: 4 | C16: =CONCATENATE(A16,B16) -> 1.4 | D16: Fortbewegen innerhalb des Wohnbereichs | T16: =IF(V16<1,0,V16-1) -> 0 | V16: 0
A17: 1. | B17: 5 | C17: =CONCATENATE(A17,B17) -> 1.5 | D17: Treppensteigen | T17: =IF(V17<1,0,V17-1) -> 0 | V17: 0
C19: Erläuterung:
A22: 1. | B22: 6 | C22: =CONCATENATE(A22,B22) -> 1.6 | D22: Besondere Bedarfskonstellation* | V22: 0
L24: Einzelpunkte | N24: =SUM(T13:U17) -> 0 | Q24: gewichtete Punkte | T24: =IF($N$24<=1,0,IF($N$24<=3,2.5,IF($N$24<=5,5,IF($N$24<=9,7.5,IF($N$24<=15,10,"Fehler"))))) -> 0
L26: Zuordnung der Punkte
K27: Einzelpunkte | L27: 0 - 1 | N27: 2 - 3 | P27: 4 - 5 | R27: 6 - 9 | T27: 10 - 15
K28: Gewichtete Punkte | L28: 0 | N28: 2.5 | P28: 5 | R28: 7.5 | T28: 10

Sheet Modul 2
A2: Navigation
C4: Formulargutachten zur Feststellung der Pflegebedürftigkeit (Erwachsene)
C5: Versicherter: | G5: ='Kap. 1, 2, 3'!G5 | Q5: Geburtsdatum: | T5: ='Kap. 1, 2, 3'!T5:U5
C6: Datum der Bearbeitung: | G6: ='Kap. 1, 2, 3'!G6:H6
C8: Kapitel 4 Module des Begutachtungsinstruments
C10: Modul 2 Kognitive und kommunikative Fähigkeiten
C12: Kriterien | L12: vorhanden/ unbeein-trächtigt | N12: größtenteils vorhanden | P12: in geringem Maße vorhanden | R12: nicht vorhanden | T12: Punkte
A13: 2. | B13: 1 | C13: =CONCATENATE(A13,B13) -> 2.1 | D13: Erkennen von Personen aus dem näheren Umfeld | T13: =IF(V13<1,0,V13-1) -> 0 | V13: 0
A14: 2. | B14: 2 | C14: =CONCATENATE(A14,B14) -> 2.2 | D14: Örtliche Orientierung | T14: =IF(V14<1,0,V14-1) -> 0 | V14: 0
A15: 2. | B15: 3 | C15: =CONCATENATE(A15,B15) -> 2.3 | D15: Zeitliche Orientierung | T15: =IF(V15<1,0,V15-1) -> 0 | V15: 0
A16: 2. | B16: 4 | C16: =CONCATENATE(A16,B16) -> 2.4 | D16: Erinnern an wesentliche Ereignisse oder Beobachtungen | T16: =IF(V16<1,0,V16-1) -> 0 | V16: 0
A17: 2. | B17: 5 | C17: =CONCATENATE(A17,B17) -> 2.5 | D17: Steuern von mehrschrittigen Alltagshandlungen | T17: =IF(V17<1,0,V17-1) -> 0 | V17: 0
A18: 2. | B18: 6 | C18: =CONCATENATE(A18,B18) -> 2.6 | D18: Treffen von Entscheidungen im Alltagsleben | T18: =IF(V18<1,0,V18-1) -> 0 | V18: 0
A19: 2. | B19: 7 | C19: =CONCATENATE(A19,B19) -> 2.7 | D19: Verstehen von Sachverhalten und Informationen | T19: =IF(V19<1,0,V19-1) -> 0 | V19: 0
A20: 2. | B20: 8 | C20: =CONCATENATE(A20,B20) -> 2.8 | D20: Erkennen von Risiken und Gefahren | T20: =IF(V20<1,0,V20-1) -> 0 | V20: 0
A21: 2. | B21: 9 | C21: =CONCATENATE(A21,B21) -> 2.9 | D21: Mitteilen von elementaren Bedürfnissen | T21: =IF(V21<1,0,V21-1) -> 0 | V21: 0
A22: 2. | B22: 10 | C22: =CONCATENATE(A22,B22) -> 2.10 | D22: Verstehen von Aufforderungen | T22: =IF(V22<1,0,V22-1) -> 0 | V22: 0
A23: 2. | B23: 11 | C23: =CONCATENATE(A23,B23) -> 2.11 | D23: Beteiligen an einem Gespräch | T23: =IF(V23<1,0,V23-1) -> 0 | V23: 0
C25: Erläuterung:
L28: Einzelpunkte | N28: =SUM(T13:U23) -> 0 | Q28: gewichtete Punkte | T28: =IF($N$28<=1,0,IF($N$28<=5,3.75,IF($N$28<=10,7.5,IF($N$28<=16,11.25,IF($N$28<=33,15,"Fehler"))))) -> 0
L30: Zuordnung der Punkte
K31: Einzelpunkte | L31: 0 - 1 | N31: 2 - 5 | P31: 6 - 10 | R31: 11 - 16 | T31: 17 - 33
K32: Gewichtete Punkte | L32: 0 | N32: 3.75 | P32: 7.5 | R32: 11.25 | T32: 15

Sheet Modul 3
A2: Navigation
C4: Formulargutachten zur Feststellung der Pflegebedürftigkeit (Erwachsene)
C5: Versicherter: | G5: ='Kap. 1, 2, 3'!G5 | Q5: Geburtsdatum: | T5: ='Kap. 1, 2, 3'!T5:U5
C6: Datum der Bearbeitung: | G6: ='Kap. 1, 2, 3'!G6:H6
C8: Kapitel 4 Module des Begutachtungsinstruments
C10: Modul 3 Verhaltensweisen und psychische Problemlagen
C12: Kriterien | L12: nie oder sehr selten | N12: selten (ein- bis dreimal innerhalb von zwei Wochen) | P12: häufig (zweimal bis mehr- mals wöchentlich, aber nicht täglich) | R12: täglich | T12: Punkte
A13: 3. | B13: 1 | C13: =CONCATENATE(A13,B13) -> 3.1 | D13: Motorisch geprägte Verhaltensauffälligkeiten | T13: =IF(V13<=1,0,IF(V13=2,1,IF(V13=3,3,IF(V13=4,5)))) -> 0 | V13: 0
A14: 3. | B14: 2 | C14: =CONCATENATE(A14,B14) -> 3.2 | D14: Nächtliche Unruhe | T14: =IF(V14<=1,0,IF(V14=2,1,IF(V14=3,3,IF(V14=4,5)))) -> 0 | V14: 0
A15: 3. | B15: 3 | C15: =CONCATENATE(A15,B15) -> 3.3 | D15: Selbstschädigendes und autoaggressives Verhalten | T15: =IF(V15<=1,0,IF(V15=2,1,IF(V15=3,3,IF(V15=4,5)))) -> 0 | V15: 0
A16: 3. | B16: 4 | C16: =CONCATENATE(A16,B16) -> 3.4 | D16: Beschädigen von Gegenständen | T16: =IF(V16<=1,0,IF(V16=2,1,IF(V16=3,3,IF(V16=4,5)))) -> 0 | V16: 0
A17: 3. | B17: 5 | C17: =CONCATENATE(A17,B17) -> 3.5 | D17: Physisch aggressives Verhalten gegenüber anderen Personen | T17: =IF(V17<=1,0,IF(V17=2,1,IF(V17=3,3,IF(V17=4,5)))) -> 0 | V17: 0
A18: 3. | B18: 6 | C18: =CONCATENATE(A18,B18) -> 3.6 | D18: Verbale Aggression | T18: =IF(V18<=1,0,IF(V18=2,1,IF(V18=3,3,IF(V18=4,5)))) -> 0 | V18: 0
A19: 3. | B19: 7 | C19: =CONCATENATE(A19,B19) -> 3.7 | D19: Andere pflegerelevante vokale Auffälligkeiten | T19: =IF(V19<=1,0,IF(V19=2,1,IF(V19=3,3,IF(V19=4,5)))) -> 0 | V19: 0
A20: 3. | B20: 8 | C20: =CONCATENATE(A20,B20) -> 3.8 | D20: Abwehr pflegerischer oder anderer unterstützender Maßnahmen | T20: =IF(V20<=1,0,IF(V20=2,1,IF(V20=3,3,IF(V20=4,5)))) -> 0 | V20: 0
A21: 3. | B21: 9 | C21: =CONCATENATE(A21,B21) -> 3.9 | D21: Wahnvorstellungen | T21: =IF(V21<=1,0,IF(V21=2,1,IF(V21=3,3,IF(V21=4,5)))) -> 0 | V21: 0
A22: 3. | B22: 10 | C22: =CONCATENATE(A22,B22) -> 3.10 | D22: Ängste | T22: =IF(V22<=1,0,IF(V22=2,1,IF(V22=3,3,IF(V22=4,5)))) -> 0 | V22: 0
A23: 3. | B23: 11 | C23: =CONCATENATE(A23,B23) -> 3.11 | D23: Antriebslosigkeit bei depressiver Stimmungslage | T23: =IF(V23<=1,0,IF(V23=2,1,IF(V23=3,3,IF(V23=4,5)))) -> 0 | V23: 0
A24: 3. | B24: 12 | C24: =CONCATENATE(A24,B24) -> 3.12 | D24: Sozial inadäquate Verhaltensweisen | T24: =IF(V24<=1,0,IF(V24=2,1,IF(V24=3,3,IF(V24=4,5)))) -> 0 | V24: 0
A25: 3. | B25: 13 | C25: =CONCATENATE(A25,B25) -> 3.13 | D25: Sonstige pflegerelevante inadäquate Handlungen | T25: =IF(V25<=1,0,IF(V25=2,1,IF(V25=3,3,IF(V25=4,5)))) -> 0 | V25: 0
C27: Erläuterung:
L30: Einzelpunkte | N30: =SUM(T13:U25) -> 0 | Q30: gewichtete Punkte | T30: =IF($N$30<=0,0,IF($N$30<3,3.75,IF($N$30<5,7.5,IF($N$30<7,11.25,IF($N$30<=65,15,"Fehler"))))) -> 0
L32: Zuordnung der Punkte
K33: Einzelpunkte | L33: 0 | N33: 1 - 2 | P33: 3 - 4 | R33: 5 - 6 | T33: 7 - 65
K34: Gewichtete Punkte | L34: 0 | N34: 3.75 | P34: 7.5 | R34: 11.25 | T34: 15

Sheet Modul 4
A2: Navigation
C4: Formulargutachten zur Feststellung der Pflegebedürftigkeit (Erwachsene)
C5: Versicherter: | G5: ='Kap. 1, 2, 3'!G5 | Q5: Geburtsdatum: | T5: ='Kap. 1, 2, 3'!T5:U5
C6: Datum der Bearbeitung: | G6: ='Kap. 1, 2, 3'!G6:H6
C8: Kapitel 4 Module des Begutachtungsinstruments
C10: Modul 4 Selbstversorgung
C12: Kriterien | L12: selbstständig | N12: überwiegend selbstständig | P12: überwiegend unselbst-ständig | R12: unselbst-ständig | T12: Punkte
A13: 4. | B13: 1 | C13: =CONCATENATE(A13,B13) -> 4.1 | D13: Waschen des vorderen Oberkörpers | T13: =IF(V13<1,0,V13-1) -> 0 | V13: 0
A14: 4. | B14: 2 | C14: =CONCATENATE(A14,B14) -> 4.2 | D14: Körperpflege im Bereich des Kopfes | T14: =IF(V14<1,0,V14-1) -> 0 | V14: 0
A15: 4. | B15: 3 | C15: =CONCATENATE(A15,B15) -> 4.3 | D15: Waschen des Intimbereichs | T15: =IF(V15<1,0,V15-1) -> 0 | V15: 0
A16: 4. | B16: 4 | C16: =CONCATENATE(A16,B16) -> 4.4 | D16: Duschen und Baden einschließlich Waschen der Haare | T16: =IF(V16<1,0,V16-1) -> 0 | V16: 0
A17: 4. | B17: 5 | C17: =CONCATENATE(A17,B17) -> 4.5 | D17: An- und Auskleiden des Oberkörpers | T17: =IF(V17<1,0,V17-1) -> 0 | V17: 0
A18: 4. | B18: 6 | C18: =CONCATENATE(A18,B18) -> 4.6 | D18: An- und Auskleiden des Unterkörpers | T18: =IF(V18<1,0,V18-1) -> 0 | V18: 0
A19: 4. | B19: 7 | C19: =CONCATENATE(A19,B19) -> 4.7 | D19: Mundgerechtes Zubereiten der Nahrung und Eingießen von Getränken | T19: =IF(V19<1,0,V19-1) -> 0 | V19: 0
A20: 4. | B20: 8 | C20: =CONCATENATE(A20,B20) -> 4.8 | D20: Essen | T20: =IF(V20<=1,0,IF(V20=2,3,IF(V20=3,6,IF(V20=4,9)))) -> 0 | V20: 0
A21: 4. | B21: 9 | C21: =CONCATENATE(A21,B21) -> 4.9 | D21: Trinken | T21: =IF(V21<=1,0,IF(V21=2,2,IF(V21=3,4,IF(V21=4,6)))) -> 0 | V21: 0
A22: 4. | B22: 10 | C22: =CONCATENATE(A22,B22) -> 4.10 | D22: Benutzen einer Toilette oder eines Toilettenstuhls | T22: =IF(V22<=1,0,IF(V22=2,2,IF(V22=3,4,IF(V22=4,6)))) -> 0 | V22: 0
A23: 4. | B23: 11 | C23: =CONCATENATE(A23,B23) -> 4.11 | D23: Bewältigen der Folgen einer Harninkontinenz und Umgang mit Dauerkatheter und Urostoma | T23: =IF(V23<1,0,V23-1) -> 0 | V23: 0
A24: 4. | B24: 12 | C24: =CONCATENATE(A24,B24) -> 4.12 | D24: Bewältigen der Folgen einer Stuhlinkontinenz und Umgang mit Stoma | T24: =IF(V24<1,0,V24-1) -> 0 | V24: 0
C26: Kriterien | L26: Versorgung selbstständig | N26: Nicht täglich, nicht auf Dauer | P26: Täglich zusätzlich zu oraler Ernährung | R26: Ausschließlich oder nahezu ausschließlich | T26: Punkte
A27: 4. | B27: 13 | C27: =CONCATENATE(A27,B27) -> 4.13 | D27: Ernährung parenteral oder über Sonde | T27: =IF(V27<=1,0,IF(V27=2,0,IF(V27=3,6,IF(V27=4,3)))) -> 0 | V27: 0
C29: Erläuterung:
L32: Einzelpunkte | N32: =SUM(T13:U24,T27) -> 0 | Q32: gewichtete Punkte | T32: =IF($N$32<=2,0,IF($N$32<8,10,IF($N$32<19,20,IF($N$32<37,30,IF($N$32<=54,40,"Fehler"))))) -> 0
L34: Zuordnung der Punkte
K35: Einzelpunkte | L35: 0 - 2 | N35: 3 - 7 | P35: 8 - 18 | R35: 19 - 36 | T35: 37 - 54
K36: Gewichtete Punkte | L36: 0 | N36: 10 | P36: 20 | R36: 30 | T36: 40
C38: Angabe zur Versorgung
C40: Blasenkontrolle/Harnkontinenz
D41: ständig kontinent (keine unwillkürlichen Harnabgänge) (4.4.11 entfällt)
D42: überwiegend kontinent (maximal einmal täglich unwillkürlicher Harnabgang oder Tröpfcheninkontinenz) (4.4.11 entfällt)
D43: überwiegend inkontinent (mehrmals täglich unwillkürliche Harnabgänge)
D44: komplett inkontinent
D45: suprapubischer Dauerkatheter
D46: transurethraler Dauerkatheter
D47: Urostoma
C48: Darmkontrolle/Stuhlkontinenz
D49: ständig kontinent (keine unwillkürlichen Stuhlabgänge) (4.4.12 entfällt)
D50: überwiegend kontinent (gelegentlich unwillkürliche Stuhlabgänge oder nur geringe Stuhlmengen, sogenannte Schmierstühle) (4.4.12 entfällt)
D51: überwiegend inkontinent, selten gesteuerte Darmentleerung
D52: komplett inkontinent
...

Sheet Modul 5
A2: Navigation
C4: Formulargutachten zur Feststellung der Pflegebedürftigkeit (Erwachsene)
C5: Versicherter: | G5: ='Kap. 1, 2, 3'!G5 | Q5: Geburtsdatum: | T5: ='Kap. 1, 2, 3'!T5:U5
C6: Datum der Bearbeitung: | G6: ='Kap. 1, 2, 3'!G6:H6
C8: Kapitel 4 Module des Begutachtungsinstruments
C10: Modul 5 Bewältigung von und selbstständiger Umgang mit krankheits- oder therapiebedingten Anforderungen und Belastungen
C12: Kriterien | L12: entfällt | N12: selbstständig | P12: Häufigkeit der Hilfe (Anzahl eintragen)
P13: pro Tag | R13: pro Woche | T13: pro Monat
A14: 5. | B14: 1 | C14: =CONCATENATE(A14,B14) -> 5.1 | D14: Medikation | V14: FALSE | W14: FALSE | X14: =IF(OR(V14=TRUE,W14=TRUE),0,1) -> 1
A15: 5. | B15: 2 | C15: =CONCATENATE(A15,B15) -> 5.2 | D15: Injektionen | V15: FALSE | W15: FALSE | X15: =IF(OR(V15=TRUE,W15=TRUE),0,1) -> 1
A16: 5. | B16: 3 | C16: =CONCATENATE(A16,B16) -> 5.3 | D16: Versorgung intravenöser Zugänge (Port) | V16: FALSE | W16: FALSE | X16: =IF(OR(V16=TRUE,W16=TRUE),0,1) -> 1
A17: 5. | B17: 4 | C17: =CONCATENATE(A17,B17) -> 5.4 | D17: Absaugen und Sauerstoffgabe | V17: FALSE | W17: FALSE | X17: =IF(OR(V17=TRUE,W17=TRUE),0,1) -> 1
A18: 5. | B18: 5 | C18: =CONCATENATE(A18,B18) -> 5.5 | D18: Einreibungen oder Kälte- und Wärmeanwendungen | V18: FALSE | W18: FALSE | X18: =IF(OR(V18=TRUE,W18=TRUE),0,1) -> 1
A19: 5. | B19: 6 | C19: =CONCATENATE(A19,B19) -> 5.6 | D19: Messung und Deutung von Körperzuständen | V19: FALSE | W19: FALSE | X19: =IF(OR(V19=TRUE,W19=TRUE),0,1) -> 1
A20: 5. | B20: 7 | C20: =CONCATENATE(A20,B20) -> 5.7 | D20: Körpernahe Hilfsmittel | V20: FALSE | W20: FALSE | X20: =IF(OR(V20=TRUE,W20=TRUE),0,1) -> 1
L22: Einzelpunkte | N22: =(P14*$X$14+P15*$X$15+P16*$X$16+P17*$X$17+P18*$X$18+P19*$X$19+P20*$X$20)+(R14*$X$14+R15*$X$15+R16*$X$16+R17*$X$17+R18*$X$18+R19*$X$19+R20*$X$20)/7+(T14*$X$14+T15*$X$15+T16*$X$16+T17*$X$17+T18*$X$18+T19*$X$19+T20*$X$20)/30 -> 0 | Q22: gewichtete Punkte | T22: =IF($N$22<1,0,IF(AND($N$22>=1,$N$22<4),1,IF(AND($N$22>=4,$N$22<=8),2,IF($N$22>8,3,"Fehler")))) -> 0
C24: Kriterien | L24: entfällt | N24: selbstständig | P24: Häufigkeit der Hilfe (Anzahl eintragen)
P25: pro Tag | R25: pro Woche | T25: pro Monat
A26: 5. | B26: 8 | C26: =CONCATENATE(A26,B26) -> 5.8 | D26: Verbandwechsel und Wundversorgung | V26: FALSE | W26: FALSE | X26: =IF(OR(V26=TRUE,W26=TRUE),0,1) -> 1
A27: 5. | B27: 9 | C27: =CONCATENATE(A27,B27) -> 5.9 | D27: Versorgung mit Stoma | V27: FALSE | W27: FALSE | X27: =IF(OR(V27=TRUE,W27=TRUE),0,1) -> 1
A28: 5. | B28: 10 | C28: =CONCATENATE(A28,B28) -> 5.10 | D28: Regelmäßige Einmalkatheterisierung und Nutzung von Abführmethoden | V28: FALSE | W28: FALSE | X28: =IF(OR(V28=TRUE,W28=TRUE),0,1) -> 1
A29: 5. | B29: 11 | C29: =CONCATENATE(A29,B29) -> 5.11 | D29: Therapiemaßnahmen in häuslicher Umgebung | V29: FALSE | W29: FALSE | X29: =IF(OR(V29=TRUE,W29=TRUE),0,1) -> 1
L31: Einzelpunkte | N31: =(P26*$X$26+P27*$X$27+P28*$X$28+P29*$X$29)+(R26*$X$26+R27*$X$27+R28*$X$28+R29*$X$29)/7+(T26*$X$26+T27*$X$27+T28*$X$28+T29*$X$29)/30 -> 0 | Q31: gewichtete Punkte | T31: =IF($N31<(1/7),0,IF(AND($N31>=(1/7),$N31<1),1,IF(AND($N31>=1,$N31<3),2,IF($N31>=3,3,"Fehler")))) -> 0
C33: Kriterien | L33: entfällt | N33: selbstständig | P33: Häufigkeit der Hilfe (Anzahl eintragen)
P34: pro Tag | R34: pro Woche | T34: pro Monat
A35: 5. | B35: 12 | C35: =CONCATENATE(A35,B35) -> 5.12 | D35: Zeit- und technikintensive Maßnahmen in häuslicher Umgebung | V35: FALSE | W35: FALSE | X35: =IF(OR(V35=TRUE,W35=TRUE),0,1) -> 1
A36: 5. | B36: 13 | C36: =CONCATENATE(A36,B36) -> 5.13 | D36: Arztbesuche | V36: FALSE | W36: FALSE | X36: =IF(OR(V36=TRUE,W36=TRUE),0,1) -> 1
A37: 5. | B37: 14 | C37: =CONCATENATE(A37,B37) -> 5.14 | D37: Besuch anderer medizinischer oder therapeutischer Einrichtungen (bis zu 3 Std.) | V37: FALSE | W37: FALSE | X37: =IF(OR(V37=TRUE,W37=TRUE),0,1) -> 1
A38: 5. | B38: 15 | C38: =CONCATENATE(A38,B38) -> 5.15 | D38: Zeitlich ausgedehnte Besuche anderer medizinischer oder therapeutischer Einrichtungen (länger als 3 Std.) | V38: FALSE | W38: FALSE | X38: =IF(OR(V38=TRUE,W38=TRUE),0,1) -> 1
C40: Erläuterung:
L43: Einzelpunkte | N43: =(P35*60+R35*8.6+T35*2)*$X$35+(R36*4.3+T36*1)*$X$36+(R37*4.3+T37*1)*$X$37+(R38*8.6+T38*2)*$X$38 -> 0 | Q43: gewichtete Punkte | T43: =IF($N$43<4.3,0,IF(AND($N$43>=4.3,$N$43<8.6),1,IF(AND($N$43>=8.6,$N$43<12.9),2,IF(AND($N$43>=12.9,$N$43<60),3,IF($N$43>=60,6,"Fehler"))))) -> 0
C45: Einhaltung einer Diät und anderer krankheits- oder therapiebedingter Verhaltensvorschriften, und zwar:
C48: Kriterien | L48: entfällt/ nicht erforderlich | N48: selbstständig | P48: überwiegend selbstständig | R48: überwiegend unselbst-ständig | T48: unselbst-ständig
A49: 5. | B49: 16 | C49: =CONCATENATE(A49,B49) -> 5.16 | D49: Einhaltung einer Diät und anderer krankheits- oder therapiebedingter Verhaltensvorschriften, und zwar: | V49: 0
R50: Einzelpunkte/ Gewichtete Punkte | T50: =IF(V49<=2,0,IF(V49=3,1,IF(V49=4,2,IF(V49=5,3)))) -> 0
C52: Erläuterung:
J55: Gewichtete Punkte Items | N55: =T22+T31+T43+T50 -> 0 | P55: Gewichtete Punkte Modul | T55: =IF($N$55<=0,0,IF($N$55<2,5,IF($N$55<4,10,IF($N$55<6,15,IF($N$55<=15,20,"Fehler"))))) -> 0
L57: Zuordnung der Punkte
K58: Gewichtete Punkte Items | L58: 0 | N58: 1 | P58: 2 - 3 | R58: 4 - 5 | T58: 6 - 15
K59: Gewichtete Punkte Modul | L59: 0 | N59: 5 | P59: 10 | R59: 15 | T59: 20
...

Sheet Modul 6
A2: Navigation
C4: Formulargutachten zur Feststellung der Pflegebedürftigkeit (Erwachsene)
C5: Versicherter: | G5: ='Kap. 1, 2, 3'!G5 | Q5: Geburtsdatum: | T5: ='Kap. 1, 2, 3'!T5:U5
C6: Datum der Bearbeitung: | G6: ='Kap. 1, 2, 3'!G6:H6
C8: Kapitel 4 Module des Begutachtungsinstruments
C10: Modul 6 Gestaltung des Alltagslebens und sozialer Kontakte
C12: Kriterien | L12: selbstständig | N12: überwiegend selbstständig | P12: überwiegend unselbst-ständig | R12: unselbst-ständig | T12: Punkte
A13: 6. | B13: 1 | C13: =CONCATENATE(A13,B13) -> 6.1 | D13: Gestaltung des Tagesablaufs und Anpassung an Veränderungen | T13: =IF(V13<1,0,V13-1) -> 0 | V13: 0
A14: 6. | B14: 2 | C14: =CONCATENATE(A14,B14) -> 6.2 | D14: Ruhen und Schlafen | T14: =IF(V14<1,0,V14-1) -> 0 | V14: 0
A15: 6. | B15: 3 | C15: =CONCATENATE(A15,B15) -> 6.3 | D15: Sichbeschäftigen | T15: =IF(V15<1,0,V15-1) -> 0 | V15: 0
A16: 6. | B16: 4 | C16: =CONCATENATE(A16,B16) -> 6.4 | D16: Vornehmen von in die Zukunft gerichteten Planungen | T16: =IF(V16<1,0,V16-1) -> 0 | V16: 0
A17: 6. | B17: 5 | C17: =CONCATENATE(A17,B17) -> 6.5 | D17: Interaktion mit Personen im direkten Kontakt | T17: =IF(V17<1,0,V17-1) -> 0 | V17: 0
A18: 6. | B18: 6 | C18: =CONCATENATE(A18,B18) -> 6.6 | D18: Kontaktpflege zu Personen außerhalb des direkten Umfeldes | T18: =IF(V18<1,0,V18-1) -> 0 | V18: 0
C20: Erläuterung:
L23: Einzelpunkte | N23: =SUM(T13:U18) -> 0 | Q23: gewichtete Punkte | T23: =IF($N$23<=0,0,IF($N$23<4,3.75,IF($N$23<7,7.5,IF($N$23<12,11.25,IF($N$23<=18,15,"Fehler"))))) -> 0
L25: Zuordnung der Punkte
K26: Einzelpunkte | L26: 0 | N26: 1 - 3 | P26: 4 - 6 | R26: 7 - 11 | T26: 12 - 18
K27: Gewichtete Punkte | L27: 0 | N27: 3.75 | P27: 7.5 | R27: 11.25 | T27: 15

Sheet Kap. 5 Pflegegrad
A2: Navigation
C4: Formulargutachten zur Feststellung der Pflegebedürftigkeit (Erwachsene)
C5: Versicherter: | G5: ='Kap. 1, 2, 3'!G5 | Q5: Geburtsdatum: | T5: ='Kap. 1, 2, 3'!T5:U5
C6: Datum der Bearbeitung: | G6: ='Kap. 1, 2, 3'!G6:H6
C8: Kapitel 5 Ergebnis der Begutachtung
C10: Modulbewertung
C12: Modul | E12: Modulbezeichnung | S12: gewichtete Punkte
C13: Modul 1 | E13: Mobilität | S13: ='Modul 1'!T24 -> 0
C14: Modul 2 | E14: Kognitive und kommunikative Fähigkeiten | S14: ='Modul 2'!T28 -> 0
C15: Modul 3 | E15: Verhaltensweisen und psychische Problemlagen | S15: ='Modul 3'!T30 -> 0
C16: Modul 4 | E16: Selbstversorgung | S16: ='Modul 4'!T32 -> 0
C17: Modul 5 | E17: Bewältigung von und selbstständiger Umgang mit krankheits- oder therapiebedingten Anforderungen und Belastungen | S17: ='Modul 5'!T55 -> 0
C18: Modul 6 | E18: Gestaltung des Alltagslebens und sozialer Kontakte | S18: ='Modul 6'!T23 -> 0
R20: Summe der gewichteten Punkte | S20: =S13+S16+S17+S18+MAX(S14:U15) -> 0
C22: Besondere Bedarfskonstellation 4.1.6 | S22: =IF('Modul 1'!V22=1,"ja","nein") -> nein
A24: 5. | B24: 1 | C24: =CONCATENATE(A24,B24) -> 5.1 | D24: Pflegegrad
C26: Pflegegrad
C28: Punkte | F28: Pflegegrad | I28: Beschreibung | S28: Status
C29: unter 12,5 Pkt. | F29: kein Pflegegrad | I29: keine | S29: =IF(AND($S$20<12.5,$S$22="nein"),F29,"") -> kein Pflegegrad
C30: 12,5 – <27 Pkt. | F30: Pflegegrad 1 | I30: geringe Beeinträchtigung der Selbstständigkeit oder der Fähigkeiten | S30: =IF(AND(AND($S$20>=12.5,$S$20<27),$S$22="nein"),$F$30,"")
C31: 27 – <47,5 Pkt. | F31: Pflegegrad 2 | I31: erhebliche Beeinträchtigung der Selbstständigkeit oder der Fähigkeiten) | S31: =IF(AND(AND($S$20>=27,$S$20<47.5),$S$22="nein"),$F$31,"")
C32: 47,5 – <70 Pkt. | F32: Pflegegrad 3 | I32: schwere Beeinträchtigung der Selbstständigkeit oder der Fähigkeiten | S32: =IF(AND(AND($S$20>=47.5,$S$20<70),$S$22="nein"),$F$32,"")
C33: 70 – <90 Pkt. | F33: Pflegegrad 4 | I33: schwerste Beeinträchtigung der Selbstständigkeit oder der Fähigkeiten | S33: =IF(AND(AND($S$20>=70,$S$20<90),$S$22="nein"),$F$33,"")
C34: 90 – 100 Pkt.* | F34: Pflegegrad 5 | I34: schwerste Beeinträchtigung der Selbstständigkeit oder der Fähigkeiten mit besonderen Anforderungen an die pflegerische Versorgung | S34: =IF(OR(AND($S$20>=90,$S$20<=100),$S$22="ja"),$F$34,"")
C35: * oder Vorliegen der besonderen Bedarfskonstellation 4.1.6
C37: Seit wann?
C39: Wird eine Befristung empfohlen?
C43: Begründung/Erläuterung:
C46: Widerspruchsbegutachtung
C47: Wird mit diesem Gutachten das Ergebnis des Vorgutachtens bestätigt?
D49: Ja, aktuell wird der gleiche Pflegegrad empfohlen.
D50: Ja, aber aufgrund einer zwischenzeitlich eingetretenen Veränderung wird ein anderer Pflegegrad empfohlen.
D51: Nein, zum Zeitpunkt der Vorbegutachtung bestanden bereits die Voraussetzungen für den aktuell empfohlenen Pflegegrad.
A53: 5. | B53: 2 | C53: =CONCATENATE(A53,B53) -> 5.2 | D53: Pflegerelevante Aspekte der Versorgungs- und Wohnsituation
C55: Übernahme aus 1.4 | M55: Liegt der Pflegeaufwand nachvollziehbar bei wenigstens zehn Stunden verteilt auf regelmäßig mindestens zwei Tage pro Woche? | P55: wenn nein:
C56: Pflege durch | I56: Angegebene Pflegetage pro Woche | K56: Angegebene Pflege-stunden pro Woche | P56: Mindeststundenzahl von zehn Stunden wöchentlich, verteilt auf regelmäßig mindestens zwei Tage in der Woche, wird nicht erreicht: Angegebene Anzahl weiterer durch die Pflegeperson gepflegten Pflegebedürftige | S56: Sind die Angaben zur Verteilung und zum Umfang des Pflegeaufwandes nachvollziehbar?
C57: =IF('Kap. 1, 2, 3'!F180<>"",'Kap. 1, 2, 3'!F180,"") | I57: =IF('Kap. 1, 2, 3'!L180<>"",'Kap. 1, 2, 3'!L180,"") | K57: =IF('Kap. 1, 2, 3'!O180<>"",'Kap. 1, 2, 3'!O180,"")
C58: =IF('Kap. 1, 2, 3'!F181<>"",'Kap. 1, 2, 3'!F181,"")
C59: =IF('Kap. 1, 2, 3'!F182<>"",'Kap. 1, 2, 3'!F182,"")
C60: =IF('Kap. 1, 2, 3'!F183<>"",'Kap. 1, 2, 3'!F183,"")
...

Sheet Kap. 6, 7, 8, 9
A2: Navigation
C4: Formulargutachten zur Feststellung der Pflegebedürftigkeit (Erwachsene)
C5: Versicherter: | G5: ='Kap. 1, 2, 3'!G5 | Q5: Geburtsdatum: | T5: ='Kap. 1, 2, 3'!T5:U5
C6: Datum der Bearbeitung: | G6: ='Kap. 1, 2, 3'!G6:H6
C8: Kapitel 6 Erhebung weiterer versorgungsrelevanter Informationen
A10: 6. | B10: 1 | C10: =CONCATENATE(A10,B10) -> 6.1 | D10: Außerhäusliche Aktivitäten
C12: Fortbewegung im außerhäuslichen Bereich
A13: 6. | B13: 1.1 | C13: =CONCATENATE(A13,B13) -> 6.1.1 | D13: Verlassen des Bereichs der Wohnung oder der Einrichtung
O14: Auswahlmenü
A17: 6. | B17: 1.2 | C17: =CONCATENATE(A17,B17) -> 6.1.2 | D17: Fortbewegung außerhalb der Wohnung oder der Einrichtung (zu Fuß oder mit dem Rollstuhl)
O18: Auswahlmenü
A21: 6. | B21: 1.3 | C21: =CONCATENATE(A21,B21) -> 6.1.3 | D21: Nutzung öffentlicher Verkehrsmittel im Nahverkehr
O22: Auswahlmenü
A25: 6. | B25: 1.4 | C25: =CONCATENATE(A25,B25) -> 6.1.4 | D25: Mitfahren in einem Kraftfahrzeug
P26: Auswahlmenü
C29: Erläuterung (6.1.1 bis 6.1.4):
C32: Teilnahme an Aktivitäten (Beurteilung ohne Berücksichtigung von Wegstrecken)
A33: 6. | B33: 1.5 | C33: =CONCATENATE(A33,B33) -> 6.1.5 | D33: Teilnahme an kulturellen, religiösen oder sportlichen Veranstaltungen
O34: Auswahlmenü
C37: Erläuterung(en):
A40: 6. | B40: 1.6 | C40: =CONCATENATE(A40,B40) -> 6.1.6 | D40: Besuch eines Arbeitsplatzes, einer Werkstatt für behinderte Menschen oder einer Einrichtung der Tages- oder Nachtpflege oder eines Tagesbetreuungsangebotes
D43: Schule
D45: Kindergarten, Kindertagesstätte, Kinderhort
D47: Werkstatt für behinderte Menschen
D49: Tages- oder Nachtpflegeeinrichtung
D51: Tagesbetreuung
D53: niedrigschwellige Angebote
D55: keine
A58: 6. | B58: 1.7 | C58: =CONCATENATE(A58,B58) -> 6.1.7 | D58: Teilnahme an sonstigen Aktivitäten mit anderen Menschen (Besuche, organisierte Freizeitaktivitäten, Selbsthilfegruppen, Vereine etc.)
O59: Auswahlmenü
C62: Erläuterung(en):
A65: 6. | B65: 2 | C65: =CONCATENATE(A65,B65) -> 6.2 | D65: Haushaltsführung
C67: Zu bewerten ist, ob die Person die jeweilige Aktivität praktisch durchführen kann. Es ist unerheblich, ob die Beeinträchtigungen der Selbständigkeit aufgrund von Schädigungen somatischer oder mentaler Funktionen bestehen oder ob Teilaspekte bereits in anderen Modulen bewertet wurden.
C69: Kriterien | J69: selbstständig | M69: überwiegend selbstständig | P69: überwiegend unselbstständig | S69: unselbstständig
C70: Einkaufen für den täglichen Bedarf
C71: Zubereitung einfacher Mahlzeiten
C72: Einfache Aufräum- und Reinigungsarbeiten
C73: Aufwendige Aufräum- und Reinigungsarbeiten, einschließlich Wäschepflege
C74: Nutzung von Dienstleistungen
C75: Umgang mit finanziellen Angelegenheiten
...

Sheet #
A10: Anlass des Antrags/Auftrags | B10: Art des Antrags/Gutachtenart | C10: Erledigungsart | D10: Erledigungsort | E10: Ist aktuell ein Rehabilitationsantrag gestellt? | F10: Präsenz der Pflegeperson(en) in Rufnähe am Tage | G10: Nächtliche Unterstützung | H10: Verlassen des Bereichs der Wohnung oder der Einrichtung | I10: Fortbewegung außerhalb der Wohnung oder der Einrichtung (zu Fuß oder mit dem Rollstuhl) | J10: Nutzung öffentlicher Verkehrsmittel im Nahverkehr | K10: Mitfahren in einem Kraftfahrzeug | L10: Diese Auswahloptionen kommen nur bei bestimmten Personen in Betracht. Bei Mehrfachauswahl ist jede Auswahl einzeln zu bewerten. | M10: Teilnahme an kulturellen, religiösen oder sportlichen Veranstaltungen | N10: Teilnahme an sonstigen Aktivitäten mit anderen Menschen
A11: Pflegegeld (§ 37 SGB XI) | B11: Erstantrag | C11: Persönliche Befunderhebung | D11: Häusliches Wohnumfeld der oder des Versicherten | E11: nein | F11: nein | G11: nie oder max. einmal wöchentlich | H11: selbständig (ohne Begleitung) | I11: selbständig (ohne Begleitung) | J11: selbständig (ohne Begleitung) | K11: selbständig | L11: Teilnahme ist selbständig möglich | M11: Teilnahme selbständig möglich | N11: Teilnahme ist selbständig möglich
A12: Ambulante Pflegesachleistungen (§ 36 SGB XI) | B12: Erstantrag nach Eilbegutachtung | C12: Aktenlage, da antragstellende Person verstorben | D12: Vollstationäre Pflegeeinrichtung | E12: ja, aber noch nicht genehmigt | F12: mehrmals täglich | G12: mehrmals wöchentlich | H12: überwiegend selbständig (mit Unterstützung, aber auch mit Eigenaktivität der Person) | I12: nur auf gewohnten Wegen selbständig | J12: nur auf gewohnten Strecken selbständig | K12: benötigt nur Hilfe beim Ein-/Aussteigen (Hilfsperson während der Fahrt ist nicht erforderlich) | L12: nicht selbständig, Teilnahme ist nur mit unterstützender Begleitung möglich | M12: nicht selbständig, Teilnahme ist nur mit unterstützender Begleitung möglich | N12: nicht selbständig, Teilnahme ist nur mit unterstützender Begleitung möglich
A13: Kombinationsleistung (§ 38 SGB XI) | B13: Rückstufungsantrag | C13: Aktenlage, da persönliche Befunderhebung nicht zumutbar | D13: Kurzzeitpflegeeinrichtung | E13: ja, Genehmigung liegt vor | F13: überwiegend | G13: einmal pro Nacht | H13: überwiegend/völlig unselbständig, Hilfe durch eine Person reicht jedoch aus | I13: auf allen Wegen nur mit personeller Hilfe möglich | J13: auf allen Strecken nur mit personeller Hilfe möglich | K13: benötigt Hilfe (auch) während der Fahrt mit dem PKW/Taxi (zusätzlich zum Fahrer) | L13: Teilnahme ist auch mit unterstützender Begleitung nicht möglich | M13: Teilnahme ist auch mit unterstützender Begleitung nicht möglich | N13: Teilnahme ist auch mit unterstützender Begleitung nicht möglich
A14: Kurzzeitpflege (§ 42 SGB XI) | B14: Höherstufungsantrag | C14: Aktenlage aus sonstigen Gründen, Begründung: | D14: Teilstationäre Pflegeeinrichtung | F14: durchgehend | G14: mehrmals nachts | H14: überwiegend/völlig unselbständig, Hilfe durch zwei Personen erforderlich | I14: auch mit personeller Hilfe nicht möglich | J14: auch mit personeller Hilfe nicht möglich | K14: nicht möglich, Liegendtransport oder Transport im Rollstuhl (Spezialfahrzeuge) notwendig
A15: Teilstationäre Pflege (§ 41 SGB XI) | B15: Wiederholungsbegutachtung | D15: Vollstationäre Einrichtungen der Hilfe für behinderte Menschen
A16: Vollstationäre Pflege (§ 43 SGB XI) | B16: Widerspruch | D16: Hospiz
A17: Pflege in vollstationären Einrichtungen der Hilfe für behinderte Menschen (§ 43a SGB XI) | D17: Rehabilitationseinrichtung
A18: Entlastungsbetrag (§ 45b SGB XI) | D18: Krankenhaus
D19: Sonstiges
